[32mINFO    [0m root:setupMicroplan.py:32 ***************Opening URL: https://health-demo.digit.org/microplan-ui/employee/user/login*****************
[32mINFO    [0m root:setupMicroplan.py:34 *****************Performing login actions*******************
[32mINFO    [0m root:setupMicroplan.py:43 ***********Logging successful***************
[32mINFO    [0m root:setupMicroplan.py:54 **********Microplan name initiated*****************
[32mINFO    [0m root:setupMicroplan.py:62 ***************Selecting boundaries*****************
[32mINFO    [0m root:setupMicroplan.py:74 *******Boundaries for Microplan are selected********
[32mINFO    [0m root:setupMicroplan.py:80 ********Population excel uploaded successfully*******
[32mINFO    [0m root:setupMicroplan.py:83 **********Facilities excel uploaded successfully***********
[32mINFO    [0m root:setupMicroplan.py:100 *********Assumptions and estimations are successfully loaded********
[32mINFO    [0m root:setupMicroplan.py:110 ***********Users tagged successfully*********
[32mINFO    [0m root:setupMicroplan.py:120 ******Microplan created successfully******
[33mWARNING [0m urllib3.connectionpool:connectionpool.py:868 Retrying (Retry(total=2, connect=None, read=None, redirect=None, status=None)) after connection broken by 'NewConnectionError('<urllib3.connection.HTTPConnection object at 0x735238ff9e50>: Failed to establish a new connection: [Errno 111] Connection refused')': /session/a6282d08e9262627d3c0c3bb203d1676
[33mWARNING [0m urllib3.connectionpool:connectionpool.py:868 Retrying (Retry(total=1, connect=None, read=None, redirect=None, status=None)) after connection broken by 'NewConnectionError('<urllib3.connection.HTTPConnection object at 0x735238ff9f10>: Failed to establish a new connection: [Errno 111] Connection refused')': /session/a6282d08e9262627d3c0c3bb203d1676
[33mWARNING [0m urllib3.connectionpool:connectionpool.py:868 Retrying (Retry(total=0, connect=None, read=None, redirect=None, status=None)) after connection broken by 'NewConnectionError('<urllib3.connection.HTTPConnection object at 0x735238ffa0c0>: Failed to establish a new connection: [Errno 111] Connection refused')': /session/a6282d08e9262627d3c0c3bb203d1676